Traceback (most recent call last):
  File "/home/pi/Desktop/rakuten/createUrlSale.py", line 106, in <module>
    main()
  File "/home/pi/Desktop/rakuten/createUrlSale.py", line 67, in main
    chro=Chro().chrome()
  File "/home/pi/Desktop/rakuten/Chro.py", line 26, in chrome
    self.chro =  webdriver.Chrome(chrome_options=self.options, desired_capabilities=self.capabilities)
  File "/usr/local/lib/python3.5/dist-packages/selenium/webdriver/chrome/webdriver.py", line 81, in __init__
    desired_capabilities=desired_capabilities)
  File "/usr/local/lib/python3.5/dist-packages/selenium/webdriver/remote/webdriver.py", line 157, in __init__
    self.start_session(capabilities, browser_profile)
  File "/usr/local/lib/python3.5/dist-packages/selenium/webdriver/remote/webdriver.py", line 252, in start_session
    response = self.execute(Command.NEW_SESSION, parameters)
  File "/usr/local/lib/python3.5/dist-packages/selenium/webdriver/remote/webdriver.py", line 321, in execute
    self.error_handler.check_response(response)
  File "/usr/local/lib/python3.5/dist-packages/selenium/webdriver/remote/errorhandler.py", line 242, in check_response
    raise exception_class(message, screen, stacktrace)
selenium.common.exceptions.WebDriverException: Message: unknown error: Chrome failed to start: exited abnormally
  (Driver info: chromedriver=2.35 (0),platform=Linux 4.14.71-v7+ armv7l)

